#VRML_SIM R2023b utf8

EXTERNPROTO "https://raw.githubusercontent.com/cyberbotics/webots/R2023b/projects/objects/backgrounds/protos/TexturedBackground.proto"
EXTERNPROTO "https://raw.githubusercontent.com/cyberbotics/webots/R2023b/projects/objects/floors/protos/Floor.proto"
EXTERNPROTO "https://raw.githubusercontent.com/cyberbotics/webots/R2023b/projects/appearances/protos/ThreadMetalPlate.proto"
EXTERNPROTO "https://raw.githubusercontent.com/cyberbotics/webots/R2023b/projects/objects/apartment_structure/protos/Door.proto"
EXTERNPROTO "https://raw.githubusercontent.com/cyberbotics/webots/R2023b/projects/appearances/protos/GlossyPaint.proto"
EXTERNPROTO "https://raw.githubusercontent.com/cyberbotics/webots/R2023b/projects/objects/obstacles/protos/OilBarrel.proto"
EXTERNPROTO "https://raw.githubusercontent.com/cyberbotics/webots/R2023b/projects/robots/sony/aibo/protos/AiboErs7.proto"
EXTERNPROTO "https://raw.githubusercontent.com/cyberbotics/webots/R2023b/projects/objects/factory/pipes/protos/LJoint.proto"
EXTERNPROTO "https://raw.githubusercontent.com/cyberbotics/webots/R2023b/projects/objects/factory/pallet/protos/WoodenPallet.proto"
EXTERNPROTO "https://raw.githubusercontent.com/cyberbotics/webots/R2023b/projects/objects/tables/protos/Table.proto"
EXTERNPROTO "https://raw.githubusercontent.com/cyberbotics/webots/R2023b/projects/objects/factory/containers/protos/CardboardBox.proto"
EXTERNPROTO "https://raw.githubusercontent.com/cyberbotics/webots/R2023b/projects/objects/factory/tools/protos/PaintBucket.proto"
EXTERNPROTO "https://raw.githubusercontent.com/cyberbotics/webots/R2023b/projects/objects/factory/pallet/protos/WoodenPalletStack.proto"
EXTERNPROTO "https://raw.githubusercontent.com/cyberbotics/webots/R2023b/projects/objects/factory/containers/protos/WoodenBox.proto"
EXTERNPROTO "https://raw.githubusercontent.com/cyberbotics/webots/R2023b/projects/objects/factory/valves/protos/LeverValve.proto"
EXTERNPROTO "https://raw.githubusercontent.com/cyberbotics/webots/R2023b/projects/objects/factory/valves/protos/LargeValve.proto"
EXTERNPROTO "https://raw.githubusercontent.com/cyberbotics/webots/R2023b/projects/objects/factory/pipes/protos/PipeSection.proto"
EXTERNPROTO "https://raw.githubusercontent.com/cyberbotics/webots/R2023b/projects/objects/factory/valves/protos/SmallValve.proto"
EXTERNPROTO "https://raw.githubusercontent.com/cyberbotics/webots/R2023b/projects/objects/apartment_structure/protos/Wall.proto"
EXTERNPROTO "https://raw.githubusercontent.com/cyberbotics/webots/R2023b/projects/appearances/protos/Roughcast.proto"
EXTERNPROTO "https://raw.githubusercontent.com/cyberbotics/webots/R2023b/projects/objects/cabinet/protos/Cabinet.proto"
EXTERNPROTO "https://raw.githubusercontent.com/cyberbotics/webots/R2023b/projects/objects/hospital/protos/EmergencyExitSign.proto"
EXTERNPROTO "https://raw.githubusercontent.com/cyberbotics/webots/R2023b/projects/objects/stairs/protos/StraightStairsRail.proto"
EXTERNPROTO "https://raw.githubusercontent.com/cyberbotics/webots/R2023b/projects/objects/stairs/protos/StraightStairs.proto"
EXTERNPROTO "https://raw.githubusercontent.com/cyberbotics/webots/R2023b/projects/objects/factory/conveyors/protos/ConveyorBelt.proto"
EXTERNPROTO "https://raw.githubusercontent.com/cyberbotics/webots/R2023b/projects/objects/factory/tools/protos/PlatformCart.proto"
EXTERNPROTO "https://raw.githubusercontent.com/cyberbotics/webots/R2023b/projects/objects/animals/protos/Dog.proto"
EXTERNPROTO "https://raw.githubusercontent.com/cyberbotics/webots/R2023b/projects/objects/plants/protos/FlowerPot.proto"
EXTERNPROTO "https://raw.githubusercontent.com/cyberbotics/webots/R2023b/projects/robots/niryo/ned/protos/Ned.proto"
EXTERNPROTO "https://raw.githubusercontent.com/cyberbotics/webots/R2023b/projects/objects/plants/protos/PottedTree.proto"

WorldInfo {
  basicTimeStep 16
}
Viewpoint {
  orientation -0.2342768741013721 -0.24113345221689345 0.9417903187457668 4.681280339275736
  position -3.0969393464770385 3.019940870776228 8.295928197107827
}
TexturedBackground {
  texture "empty_office"
}
Ned {
  translation -8.5 -11.67 0.61
  rotation 0 0 1 -0.785395307179586
  controller "<generic>"
}
PointLight {
  attenuation 0 0 1
  intensity 15
  location -3 -3 6
}
PointLight {
  attenuation 0 0 1
  intensity 9.6
  location 2 -3 6
}
Floor {
  translation 0 -4.3 0
  name "floor(1)"
  size 20 16.4
  tileSize 1 1
  appearance ThreadMetalPlate {
  }
}
Door {
  translation 10.04 -4 3.27
  rotation 0 0 1 3.141592
  name "door(1)"
  position -0.0008932967767309736
  doorAppearance GlossyPaint {
    baseColor 0.16 0.16 0.16
  }
  frameAppearance GlossyPaint {
    baseColor 0.35 0.3503166247043564 0.35
  }
}
OilBarrel {
  translation 9.337425 2.8961435 0.44
  rotation 0 0 1 2.87325
  name "oil barrel(1)"
}
OilBarrel {
  translation 8.4218847 2.1373536 0.44
  rotation 0 0 1 2.87325
  name "oil barrel(2)"
}
OilBarrel {
  translation 8.2750954 3.0222101 0.44
  rotation 0 0 1 -0.340335
}
Door {
  translation -10.05 0 0.02
  position -0.0008932967767315131
  doorAppearance GlossyPaint {
    baseColor 0.16 0.16 0.16
  }
  frameAppearance GlossyPaint {
    baseColor 0.35 0.3503166247043564 0.35
  }
}
Floor {
  translation 0 -4.22 7
  rotation 1 0 0 3.141592
  size 20 16.4
  tileSize 1 1
  appearance PBRAppearance {
    baseColorMap ImageTexture {
      url [
        "https://raw.githubusercontent.com/cyberbotics/webots/R2023b/projects/default/worlds/textures/asphalt.jpg"
      ]
    }
    roughness 1
    metalness 0
  }
}
AiboErs7 {
  translation -5.093520001473821 -11.71329997216007 0.7535151100241319
  rotation 0.02462074306370434 0.02570040913358923 -0.9993664532999681 1.5286504138761325
  controller "<generic>"
}
LJoint {
  translation -7.571 3.19 0.712
  rotation 0 0 1 -1.5708
  name "L joint pipe(1)"
}
LJoint {
  translation -7.571 3.277 2.422
  rotation -0.577350278331609 0.577350264618634 0.577350264618634 2.094395086923155
}
WoodenPallet {
  translation -7.415 -11.9839 0.319486
  rotation -0.9999999999925853 -3.8864999999711826e-07 -3.8312799999715926e-06 1.0472
  name "wooden pallet(1)"
}
Table {
  translation 1.34117 -11.2803 0
  size 4.5 1.5 0.74
}
CardboardBox {
  translation -5.0775 -11.8077 0.31
  rotation 0 0 1 -1.5707963267948966
}
PaintBucket {
  translation -0.4737483152917235 -11.348189576925394 0.7384003971587177
  rotation 0.0030484298836082322 -0.005508000313145965 0.9999801843075667 1.0472195623378642
}
WoodenPalletStack {
  translation -6.8424942 -11.754332 0
  name "wooden pallet stack(1)"
  palletNumber 6
}
PottedTree {
  translation -5.81 -11.82 0
}
WoodenBox {
  translation 6.77078 -10.6417 0.3
  rotation -0.935113119114731 0.250562820924732 0.250562820924732 4.645351474266668
  name "wooden box(1)"
}
WoodenBox {
  translation -3.74454 -11.9092 0.3
  rotation 1 0 0 1.5707963267948966
  name "wooden box(2)"
}
WoodenBox {
  translation -2.3908 -11.8568 0.3
  rotation 0.862856210520177 0.357406743058074 0.357406743058073 1.71777151624413
  name "wooden box(3)"
}
WoodenBox {
  translation 6.93639 -11.7686 0.3
  rotation 1 0 0 1.5707963267948966
  name "wooden box(4)"
}
WoodenBox {
  translation -4.45884 -11.7657 0.3
  rotation 1 0 0 1.5707963267948966
  name "wooden box(5)"
}
WoodenBox {
  translation 6.84437 -9.36788 0.3
  rotation -0.677661491465059 0.519987933987584 0.519987933987584 4.332744312017075
  name "wooden box(6)"
}
WoodenBox {
  translation -3.12306 -11.921 0.3
  rotation 1 0 0 1.5707963267948966
  name "wooden box(7)"
}
WoodenBox {
  translation -2.59787 -12.0125 0.9
  rotation 1 0 0 1.5707963267948966
  name "wooden box(8)"
}
WoodenBox {
  translation -3.5673 -11.7065 1.45
  rotation 1 0 0 1.5707963267948966
  name "wooden box(9)"
}
WoodenBox {
  translation -3.5473 -11.7065 0.85
  rotation 1 0 0 1.5707963267948966
  name "wooden box(10)"
}
WoodenBox {
  translation -4.36873 -11.6917 0.88
  rotation 1 0 0 1.5707963267948966
}
ConveyorBelt {
  translation -8.7 -11.8 0
}
PlatformCart {
  translation -1.059825079175176 -11.520000017812547 -0.003007539637479545
  rotation 0.0015976005324052328 -0.9999987235224641 2.5019612354344957e-05 0.0013205645755409523
}
LeverValve {
  translation -7.5791585 3 0.692
  rotation 0 0 1 -1.5708
}
LargeValve {
  translation -5.7149744 2.9726835 0.706
  rotation 0 0 1 -1.5708
}
PipeSection {
  translation -7.5740452 3 0.18
  name "pipe section(1)"
  height 1.2
}
PipeSection {
  translation -5.2940471 3 0.7
  rotation 0 1 0 1.5708
  name "pipe section(2)"
  height 0.9
  radius 0.02
}
PipeSection {
  translation -7.5720026 3.234 1.56
  name "pipe section(3)"
  height 1.6
}
PipeSection {
  translation -4.8579962 3 0.35
  name "pipe section(4)"
  height 0.7
  radius 0.02
}
PipeSection {
  translation -6.6249962 3 0.70600102
  name "pipe section(5)"
  height 1.7
}
PipeSection {
  translation -7.572 3.74 2.4659975
  rotation 1 0 0 -1.5708
  name "pipe section(6)"
  height 0.8
}
PipeSection {
  translation -5.714996 3.37 0.65600436
  rotation 1 0 0 1.5708
  height 0.8
}
SmallValve {
  translation -4.8638332 3 0.707
  rotation 0 0 1 -1.5708
}
Wall {
  translation 0 3.82 0
  name "wall(1)"
  size 20 0.2 7
  appearance Roughcast {
    textureTransform TextureTransform {
      scale 5 1.75
    }
  }
}
Cabinet {
  translation -0.46 3.84 0
  rotation 0 0 1 -1.5707963267948966
  name "cabinet(1)"
  columnsWidths [
    1.3, 0.17, 0.17
  ]
  layout [
    "Shelf (1, 5, 3, 0)"
    "Shelf (1, 4, 3, 0)"
    "Shelf (1, 3, 3, 0)"
    "Shelf (1, 2, 3, 0)"
  ]
}
Cabinet {
  translation 1.49 3.84 0
  rotation 0 0 1 -1.5707963267948966
  columnsWidths [
    1, 1
  ]
  layout [
    "RightSidedDoor (1, 1, 1, 5, 1.5)"
    "LeftSidedDoor (2, 1, 1, 5, 1.5)"
  ]
}
Wall {
  translation 0 -12.5 0
  name "wall(2)"
  size 20 0.2 7
  appearance Roughcast {
    textureTransform TextureTransform {
      scale 5 1.75
    }
  }
}
Wall {
  translation -10 -4.3 0
  rotation 0 0 1 1.5708
  name "wall(3)"
  size 16.5 0.2 7
  appearance Roughcast {
    textureTransform TextureTransform {
      scale 4.125 1.725
    }
  }
}
Wall {
  translation 10 -4.3 0
  rotation 0 0 1 -1.5708
  size 16.5 0.2 7
  appearance Roughcast {
    textureTransform TextureTransform {
      scale 4.125 1.725
    }
  }
}
EmergencyExitSign {
  translation 9.82 -4.02 5.45
  rotation 0.5773509358560258 -0.577349935856137 -0.577349935856137 2.09439
}
EmergencyExitSign {
  translation -9.83 -0.01 2.3
  rotation 0.5773489358550934 0.5773519358547601 0.5773499358549823 2.0944
  name "emergency exit sign(1)"
}
Solid {
  translation -9.87 -6.36 4.13
  rotation 0.7071067811865476 0 0.7071067811865476 3.141592
  children [
    Shape {
      appearance PBRAppearance {
        baseColor 0.8 0.8 0.8
        baseColorMap ImageTexture {
          url [
            "https://raw.githubusercontent.com/cyberbotics/webots/R2023b/projects/default/worlds/textures/ladybug.png"
          ]
          filtering 5
        }
        transparency 0.6
        roughness 0.5
        metalness 0
        textureTransform TextureTransform {
          rotation 1.5708
        }
      }
      geometry Plane {
        size 5 5
      }
    }
  ]
  name "solid(3)"
}
Solid {
  translation 9.25 -3.95 3.21
  rotation 1 0 0 1.5707963267948966
  children [
    Shape {
      appearance PBRAppearance {
        baseColor 0.8 0.8 0.8
        baseColorMap ImageTexture {
          url [
            "https://raw.githubusercontent.com/cyberbotics/webots/R2023b/projects/default/worlds/textures/steel_floor.jpg"
          ]
        }
        roughness 0.5
        metalness 0
        textureTransform TextureTransform {
          scale 2 2
        }
      }
      geometry Box {
        size 1.5 0.12 2.6
      }
    }
  ]
}
StraightStairsRail {
  translation 8.52 -2.73 3.27
  rotation 0 0 1 -1.5708
  name "straight stairs rail(1)"
  run 2.5
  rise 0
  newelHeight 0.89
  balusterHeight 0.9
  nBalusters 9
  appearance PBRAppearance {
    baseColor 0.8 0.8 0.8
    roughness 0.5
    metalness 0
    textureTransform TextureTransform {
      rotation 1.5708
    }
  }
}
StraightStairsRail {
  translation 8.57 -5.23 3.27
  run 1.3
  rise 0
  newelHeight 0.89
  balusterHeight 0.9
  nBalusters 5
  appearance PBRAppearance {
    baseColor 0.8 0.8 0.8
    roughness 0.5
    metalness 0
    textureTransform TextureTransform {
      rotation 1.5708
    }
  }
}
StraightStairs {
  translation 9.201 0.17 0
  rotation 0 0 1 -1.5708
  stepSize 0.3 1.34 0.01
  stepRise 0.297
  nSteps 10
  stepAppearance PBRAppearance {
    baseColor 0.8 0.8 0.8
    roughness 0.5
    metalness 0
    textureTransform TextureTransform {
      rotation 1.5708
      scale 3 1
    }
  }
  stringerAppearance PBRAppearance {
    baseColor 0.8 0.8 0.8
    roughness 0.5
    metalness 0
    textureTransform TextureTransform {
      rotation 1.5708
      scale 3 3
    }
  }
  leftRail []
  rightRail [
    StraightStairsRail {
      run 3
      rise 2.97
      newelHeight 0.862
      balusterHeight 0.83
      nBalusters 12
      appearance PBRAppearance {
        baseColor 0.8 0.8 0.8
        roughness 0.5
        metalness 0
        textureTransform TextureTransform {
          rotation 1.5708
        }
      }
    }
  ]
}
Dog {
  translation 1.37 -11.33 0.75
  rotation 0 0 1 0.523599
}
FlowerPot {
  translation 0.07 -11.84 0.75
}
DEF UAV Robot {
  translation -0.43081 -2.83637 0.0149817
  rotation -2.20327059213943e-06 -2.18886196531885e-06 -0.9999999999951772 1.5773574107587238
  children [
    Receiver {
      channel 1
    }
    DEF camera_yaw HingeJoint {
      jointParameters HingeJointParameters {
        axis 0 0 1
        anchor 0.02 0 0.003
      }
      device [
        RotationalMotor {
          name "camera yaw"
          minPosition -1.7
          maxPosition 1.7
        }
      ]
      endPoint Solid {
        translation 0.02 0 0.003
        children [
          DEF CAMERA_PITCH_MOTOR HingeJoint {
            jointParameters DEF pitch_jointParameters HingeJointParameters {
              axis 0 1 0
              anchor 0.001 -0.002 -0.005
            }
            device [
              RotationalMotor {
                name "camera pitch"
                minPosition -0.5
                maxPosition 1.7
              }
            ]
            endPoint Solid {
              translation 0.001 -0.002 -0.005
              rotation 0 1 0 0
              children [
                DEF CAMERA_ROLL_MOTOR HingeJoint {
                  jointParameters DEF roll_jointParameters HingeJointParameters {
                    anchor 0.0025 0.003 -0.001
                  }
                  device [
                    RotationalMotor {
                      name "camera roll"
                      minPosition -2
                      maxPosition 2
                    }
                  ]
                  endPoint Solid {
                    translation 0.0025 0.003 -0.001
                    rotation 1 0 0 0
                    children [
                      Camera {
                        translation 0.03 0 0.01
                        fieldOfView 0.785
                        width 450
                        height 450
                      }
                      Transform {
                        scale 0.25 0.25 0.25
                        children [
                          Shape {
                            appearance PBRAppearance {
                              roughness 0.5
                            }
                            geometry Mesh {
                              url [
                                "https://raw.githubusercontent.com/cyberbotics/webots/R2022b/projects/robots/dji/mavic/protos/Mavic2Pro/meshes/camera_chassis.obj"
                              ]
                            }
                          }
                        ]
                      }
                    ]
                  }
                }
                Transform {
                  scale 0.25 0.25 0.25
                  children [
                    Shape {
                      appearance PBRAppearance {
                        roughness 0.5
                      }
                      geometry Mesh {
                        url [
                          "https://raw.githubusercontent.com/cyberbotics/webots/R2022b/projects/robots/dji/mavic/protos/Mavic2Pro/meshes/camera_pitch.obj"
                        ]
                      }
                    }
                  ]
                }
              ]
            }
          }
          Transform {
            scale 0.25 0.25 0.25
            children [
              Shape {
                appearance PBRAppearance {
                  roughness 0.5
                }
                geometry Mesh {
                  url [
                    "https://raw.githubusercontent.com/cyberbotics/webots/R2022b/projects/robots/dji/mavic/protos/Mavic2Pro/meshes/camera_yaw.obj"
                  ]
                }
              }
            ]
          }
        ]
      }
    }
    DEF BODY Pose {
      translation 0 0 -0.015
      children [
        Group {
        }
        CadShape {
          url [
            "https://raw.githubusercontent.com/cyberbotics/webots/R2023b/projects/robots/bitcraze/crazyflie/protos/meshes/cf2_assembly.dae"
          ]
        }
      ]
    }
    DEF MULTIRANGER Pose {
      translation 0 0 0.01
      children [
        DistanceSensor {
          rotation 0 0 1 -1.57
          name "range_right"
          lookupTable [
            0 0 0
            2 2000 0
          ]
        }
        DistanceSensor {
          rotation 0 0 1 3.14
          name "range_back"
          lookupTable [
            0 0 0
            2 2000 0
          ]
        }
        DistanceSensor {
          rotation 0 0 1 1.57
          name "range_left"
          lookupTable [
            0 0 0
            2 2000 0
          ]
        }
        DistanceSensor {
          name "range_front"
          lookupTable [
            0 0 0
            2 2000 0
          ]
        }
      ]
    }
    GPS {
      speedNoise 0.05
    }
    Gyro {
    }
    InertialUnit {
      name "inertial_unit"
    }
    DEF M1 Propeller {
      shaftAxis 0 0 1
      centerOfThrust 0.031 -0.031 0.008
      thrustConstants -4e-05 0
      torqueConstants 2.4e-06 0
      fastHelixThreshold 50
      device RotationalMotor {
        name "m1_motor"
        maxVelocity 600
        maxTorque 30
      }
      fastHelix Solid {
        translation 0.031 -0.031 0.008
        rotation 0 0 -1 5.97186700277602
        children [
          DEF FASTHELIX Shape {
            appearance PBRAppearance {
              baseColor 0.1 0.1 0.1
              baseColorMap ImageTexture {
                url [
                  "https://raw.githubusercontent.com/cyberbotics/webots/R2023b/projects/default/protos/textures/fast_helix.png"
                ]
              }
              metalness 0
            }
            geometry Cylinder {
              height 0.001
              radius 0.025
            }
          }
        ]
      }
      slowHelix Solid {
        translation 0.031 -0.031 0.008
        rotation 0 0 -1 4.9523253415397175
        children [
          DEF PROP_SHAPE Shape {
            appearance DEF PLASTIC PBRAppearance {
              baseColor 0 0 0
              metalness 0.3
            }
            geometry Mesh {
              url [
                "https://raw.githubusercontent.com/cyberbotics/webots/R2023b/projects/robots/bitcraze/crazyflie/protos/meshes/ccw_prop.dae"
              ]
            }
          }
        ]
      }
    }
    DEF M2 Propeller {
      shaftAxis 0 0 1
      centerOfThrust -0.031 -0.031 0.008
      thrustConstants 4e-05 0
      torqueConstants 2.4e-06 0
      fastHelixThreshold 50
      device RotationalMotor {
        name "m2_motor"
        maxVelocity 600
        maxTorque 30
      }
      fastHelix Solid {
        translation -0.031 -0.031 0.008
        rotation 0 0 -0.9999999999999999 2.9848620969528423
        children [
          USE FASTHELIX
        ]
      }
      slowHelix Solid {
        translation -0.031 -0.031 0.008
        rotation 0 0 1 1.3042936086253623
        children [
          USE PROP_SHAPE
        ]
      }
    }
    DEF M3 Propeller {
      shaftAxis 0 0 1
      centerOfThrust -0.031 0.031 0.008
      thrustConstants -4e-05 0
      torqueConstants 2.4e-06 0
      fastHelixThreshold 50
      device RotationalMotor {
        name "m3_motor"
        maxVelocity 600
        maxTorque 30
      }
      fastHelix Solid {
        translation -0.031 0.031 0.008
        rotation 0 0 1 2.9864416978707635
        children [
          USE FASTHELIX
        ]
      }
      slowHelix Solid {
        translation -0.031 0.031 0.008
        rotation 0 0 1 3.8508741424698645
        children [
          USE PROP_SHAPE
        ]
      }
    }
    DEF M4 Propeller {
      shaftAxis 0 0 1
      centerOfThrust 0.031 0.031 0.008
      thrustConstants 4e-05 0
      torqueConstants 2.4e-06 0
      fastHelixThreshold 50
      device RotationalMotor {
        name "m4_motor"
        maxVelocity 600
        maxTorque 30
      }
      fastHelix Solid {
        translation 0.031 0.031 0.008
        rotation 0 0 1 5.969224733642516
        children [
          USE FASTHELIX
        ]
      }
      slowHelix DEF PROP Solid {
        translation 0.031 0.031 0.007
        rotation 0 0 -0.9999999999999999 2.4588815967957305
        children [
          USE PROP_SHAPE
        ]
      }
    }
  ]
  name "Crazyflie"
  model "Bitcraze's Crazyflie"
  boundingObject Cylinder {
    height 0.03
    radius 0.05
  }
  physics Physics {
    density -1
    mass 0.05
  }
  controller "uav_controller"
  supervisor TRUE
}
DEF target Robot {
  translation -1.98001 -9.91982 1.67
  rotation 0 0 1 -1.5708053071795867
  children [
    Emitter {
      channel 1
    }
    InertialUnit {
      name "imu"
    }
    Shape {
      appearance PBRAppearance {
        baseColor 0 0 0
        roughness 1
        metalness 0
      }
      geometry Box {
        size 0.05 0.05 0.05
      }
    }
  ]
  name "target"
  controller "target_controller"
  supervisor TRUE
}
