#VRML_SIM R2023b utf8

EXTERNPROTO "https://raw.githubusercontent.com/cyberbotics/webots/R2022b/projects/objects/backgrounds/protos/TexturedBackground.proto"
EXTERNPROTO "https://raw.githubusercontent.com/cyberbotics/webots/R2022b/projects/objects/backgrounds/protos/TexturedBackgroundLight.proto"
EXTERNPROTO "https://raw.githubusercontent.com/cyberbotics/webots/2f31f823882967d57e582e7692281afca673d117/projects/objects/floors/protos/RectangleArena.proto"

WorldInfo {
  basicTimeStep 16
}
Viewpoint {
  fieldOfView 0.785
  orientation -0.21784289816575914 0.22347205450803562 0.9500551102818722 1.5965225829922747
  position -0.5193523723299152 -4.076567851842589 3.636244236046268
  follow "Crazyflie"
}
TexturedBackground {
  texture "noon_park_empty"
}
TexturedBackgroundLight {
  texture "factory"
}
DEF target Robot {
  translation -0.02 1.36 1.1
  rotation 0 0 1 1.01503e-06
  children [
    Emitter {
      channel 1
    }
    InertialUnit {
      name "imu"
    }
    Shape {
      appearance PBRAppearance {
        baseColor 0 0 0
        roughness 1
        metalness 0
      }
      geometry Box {
        size 0.02 0.02 0.02
      }
    }
  ]
  name "target"
  controller "target_controller"
  supervisor TRUE
}
Robot {
  translation -5.15213e-15 0.1 0
  rotation -9.57964e-16 9.79305e-16 1 1.57079
  children [
    Receiver {
      channel 1
    }
    DEF camera_yaw HingeJoint {
      jointParameters HingeJointParameters {
        axis 0 0 1
        anchor 0.02 0 0.003
      }
      device [
        RotationalMotor {
          name "camera yaw"
          minPosition -1.7
          maxPosition 1.7
        }
      ]
      endPoint Solid {
        translation 0.02 0 0.003
        children [
          DEF CAMERA_PITCH_MOTOR HingeJoint {
            jointParameters DEF pitch_jointParameters HingeJointParameters {
              axis 0 1 0
              anchor 0.001 -0.002 -0.005
            }
            device [
              RotationalMotor {
                name "camera pitch"
                minPosition -0.5
                maxPosition 1.7
              }
            ]
            endPoint Solid {
              translation 0.001 -0.002 -0.005
              rotation 0 1 0 0
              children [
                DEF CAMERA_ROLL_MOTOR HingeJoint {
                  jointParameters DEF roll_jointParameters HingeJointParameters {
                    anchor 0.0025 0.003 -0.001
                  }
                  device [
                    RotationalMotor {
                      name "camera roll"
                      minPosition -0.5
                      maxPosition 0.5
                    }
                  ]
                  endPoint Solid {
                    translation 0.0025 0.003 -0.001
                    rotation 1 0 0 0
                    children [
                      Camera {
                        translation 0.03 0 0.01
                        fieldOfView 0.785
                        width 450
                        height 450
                      }
                      Transform {
                        scale 0.25 0.25 0.25
                        children [
                          Shape {
                            appearance PBRAppearance {
                              roughness 0.5
                            }
                            geometry Mesh {
                              url [
                                "https://raw.githubusercontent.com/cyberbotics/webots/R2022b/projects/robots/dji/mavic/protos/Mavic2Pro/meshes/camera_chassis.obj"
                              ]
                            }
                          }
                        ]
                      }
                    ]
                  }
                }
                Transform {
                  scale 0.25 0.25 0.25
                  children [
                    Shape {
                      appearance PBRAppearance {
                        roughness 0.5
                      }
                      geometry Mesh {
                        url [
                          "https://raw.githubusercontent.com/cyberbotics/webots/R2022b/projects/robots/dji/mavic/protos/Mavic2Pro/meshes/camera_pitch.obj"
                        ]
                      }
                    }
                  ]
                }
              ]
            }
          }
          Transform {
            scale 0.25 0.25 0.25
            children [
              Shape {
                appearance PBRAppearance {
                  roughness 0.5
                }
                geometry Mesh {
                  url [
                    "https://raw.githubusercontent.com/cyberbotics/webots/R2022b/projects/robots/dji/mavic/protos/Mavic2Pro/meshes/camera_yaw.obj"
                  ]
                }
              }
            ]
          }
        ]
      }
    }
    DEF BODY Pose {
      translation 0 0 -0.015
      children [
        Group {
        }
        CadShape {
          url [
            "https://raw.githubusercontent.com/cyberbotics/webots/R2023b/projects/robots/bitcraze/crazyflie/protos/meshes/cf2_assembly.dae"
          ]
        }
      ]
    }
    DEF MULTIRANGER Pose {
      translation 0 0 0.01
      children [
        DistanceSensor {
          rotation 0 0 1 -1.57
          name "range_right"
          lookupTable [
            0 0 0
            2 2000 0
          ]
        }
        DistanceSensor {
          rotation 0 0 1 3.14
          name "range_back"
          lookupTable [
            0 0 0
            2 2000 0
          ]
        }
        DistanceSensor {
          rotation 0 0 1 1.57
          name "range_left"
          lookupTable [
            0 0 0
            2 2000 0
          ]
        }
        DistanceSensor {
          name "range_front"
          lookupTable [
            0 0 0
            2 2000 0
          ]
        }
      ]
    }
    GPS {
    }
    Gyro {
    }
    InertialUnit {
      name "inertial_unit"
    }
    DEF M1 Propeller {
      shaftAxis 0 0 1
      centerOfThrust 0.031 -0.031 0.008
      thrustConstants -4e-05 0
      torqueConstants 2.4e-06 0
      fastHelixThreshold 50
      device RotationalMotor {
        name "m1_motor"
        maxVelocity 600
        maxTorque 30
      }
      fastHelix Solid {
        translation 0.031 -0.031 0.008
        children [
          DEF FASTHELIX Shape {
            appearance PBRAppearance {
              baseColor 0.1 0.1 0.1
              baseColorMap ImageTexture {
                url [
                  "https://raw.githubusercontent.com/cyberbotics/webots/R2023b/projects/default/protos/textures/fast_helix.png"
                ]
              }
              metalness 0
            }
            geometry Cylinder {
              height 0.001
              radius 0.025
            }
          }
        ]
      }
      slowHelix Solid {
        translation 0.031 -0.031 0.008
        rotation 0 0 1 2.5208980090390236
        children [
          DEF PROP_SHAPE Shape {
            appearance DEF PLASTIC PBRAppearance {
              baseColor 0 0 0
              metalness 0.3
            }
            geometry Mesh {
              url [
                "https://raw.githubusercontent.com/cyberbotics/webots/R2023b/projects/robots/bitcraze/crazyflie/protos/meshes/ccw_prop.dae"
              ]
            }
          }
        ]
      }
    }
    DEF M2 Propeller {
      shaftAxis 0 0 1
      centerOfThrust -0.031 -0.031 0.008
      thrustConstants 4e-05 0
      torqueConstants 2.4e-06 0
      fastHelixThreshold 50
      device RotationalMotor {
        name "m2_motor"
        maxVelocity 600
        maxTorque 30
      }
      fastHelix Solid {
        translation -0.031 -0.031 0.008
        children [
          USE FASTHELIX
        ]
      }
      slowHelix Solid {
        translation -0.031 -0.031 0.008
        rotation 0 0 1 2.6342726053201466
        children [
          USE PROP_SHAPE
        ]
      }
    }
    DEF M3 Propeller {
      shaftAxis 0 0 1
      centerOfThrust -0.031 0.031 0.008
      thrustConstants -4e-05 0
      torqueConstants 2.4e-06 0
      fastHelixThreshold 50
      device RotationalMotor {
        name "m3_motor"
        maxVelocity 600
        maxTorque 30
      }
      fastHelix Solid {
        translation -0.031 0.031 0.008
        children [
          USE FASTHELIX
        ]
      }
      slowHelix Solid {
        translation -0.031 0.031 0.008
        rotation 0 0 1 2.5208980090390236
        children [
          USE PROP_SHAPE
        ]
      }
    }
    DEF M4 Propeller {
      shaftAxis 0 0 1
      centerOfThrust 0.031 0.031 0.008
      thrustConstants 4e-05 0
      torqueConstants 2.4e-06 0
      fastHelixThreshold 50
      device RotationalMotor {
        name "m4_motor"
        maxVelocity 600
        maxTorque 30
      }
      fastHelix Solid {
        translation 0.031 0.031 0.008
        children [
          USE FASTHELIX
        ]
      }
      slowHelix DEF PROP Solid {
        translation 0.031 0.031 0.007
        rotation 0 0 1 2.6342726053201466
        children [
          USE PROP_SHAPE
        ]
      }
    }
  ]
  name "Crazyflie"
  model "Bitcraze's Crazyflie"
  boundingObject Cylinder {
    height 0.03
    radius 0.05
  }
  physics Physics {
    density -1
    mass 0.05
  }
  controller "uav_controller"
  supervisor TRUE
}
RectangleArena {
  translation 0 0.09 -0.02
  floorSize 0.15 0.15
  floorAppearance NULL
  wallHeight 0.01
  wallAppearance NULL
}
